Workbook

Sheet README
A1: AI Legal Status Tracker - Reference Register
A2: Phase 1, steps 1-2: reference extraction and DM corpus dedupe
A4: Source document | B4: Smith, A., Caviola, L., & Alexander, H. (2026). Denying Personhood to AI: An Analysis of U.S. State Legislation on AI Legal Status. SSRN 6829981. Reference list pp. 42-50, Table of Cases p. 41.
A5: Dedupe target | B5: digital-minds-corpus/master-corpus.csv - layers core + canon (1,279 works). Matched on normalised title, threshold 0.85, containment-boosted. Zero ambiguous matches.
A7: SHEET: Literature | B7: The working set for the literature review. Combines (a) the scholarly subset of the paper's references and (b) the personhood / legal-status cluster already held in the DM corpus but not cited by the paper. Filter on 'in_paper' and 'in_corpus' to separate the two.
A8: SHEET: Evidence | B8: Non-scholarly reference entries - testimony, news, advocacy, legislature records, social posts. These are evidence ABOUT the bills, not literature. They are source records for the bill registry in Phase 2, keyed by jurisdiction and related_bill.
A9: SHEET: Cases | B9: Table of Cases from the paper (p. 41). Primary law, not literature; relevant to the legal-vulnerabilities analysis.
A10: SHEET: Summary | B10: Counts, computed by formula from the sheets above.
A12: Column: tier | B12: core = substantive scholarship for the review. marginal = think-tank reports, trade commentary and industry essays; context rather than literature. Decide at the checkpoint whether marginal enters the registry.
A13: Column: strand | B13: Descriptive topic tag. Flat, non-hierarchical, no ranking - consistent with the Observatory descriptive-first principle.
A14: Column: action | B14: 'No action - already held' = in the corpus. 'Collect' = new, core tier, obtain in step 3. 'Hold (marginal)' = park pending checkpoint. 'Classify for tracker' = corpus-held work the paper missed.
A15: Column: cited_by | B15: Citation count as recorded in the DM corpus at its own as-of date. Blank for works not in the corpus. Not independently re-verified here.
A17: Editable cells | B17: The 'notes' column on Literature and Evidence is intended for reviewer comment. Everything else is generated - re-run build_workbook.py rather than editing in place.
A18: Assumptions | B18: (1) Op-eds by parties to the debate (Berg & Rosenblatt 2025; Alexander & Simon 2025) are classed as evidence, not literature, because they argue about the bills rather than contribute peer-reviewed analysis. (2) SEP entries and the International AI Safety Report are treated as scholarship. (3) Aquinas and Genesis are primary religious sources, not literature.
... A20: Provenance | B20: Reference data transcribed from the source PDF by hand; corpus fields read from master-corpus.csv. Titles and URLs not re-verified against publishers - do that during step 3 collection.

Sheet Literature
A1: ref_key | B1: in_paper | C1: in_corpus | D1: corpus_layer | E1: tier | F1: strand | G1: authors | H1: year | I1: title | J1: venue | K1: type | L1: discipline | M1: themes | N1: cited_by | O1: url_or_id | P1: action | Q1: notes
A2: chopra2011 | B2: Yes | C2: Yes | D2: adjacent | E2: core | F2: legal_personhood | G2: Chopra, S.; White, L. F. | H2: 2011 | I2: A Legal Theory for Autonomous Artificial Agents | J2: University of Michigan Press | K2: book | N2: 234 | O2: https://www.fulcrum.org/concern/monographs/wp988k715 | P2: No action - already held
A3: wang2026 | B3: Yes | C3: No | E3: core | F3: architectures | G3: Wang, et al. | H3: 2026 | I3: Advances in Brain-Computer Interfaces (BCI): Challenges and Opportunities | J3: Biomimetics | K3: article | O3: https://www.mdpi.com/2313-7673/11/2/157 | P3: Collect
A4: schwitzgebel2025 | B4: Yes | C4: Yes | D4: core | E4: core | F4: consciousness | G4: Schwitzgebel, E. | H4: 2025 | I4: AI and Consciousness | J4: arXiv 2510.09858 | K4: preprint | L4: computer_science_ai | M4: consciousness_theory | N4: 3 | O4: https://arxiv.org/abs/2510.09858 | P4: No action - already held
A5: novelli2025 | B5: Yes | C5: Yes | D5: adjacent | E5: core | F5: legal_personhood | G5: Novelli, C.; Floridi, L.; Sartor, G.; Teubner, G. | H5: 2025 | I5: AI as legal persons: past, patterns, and prospects | J5: Journal of Law and Society 52(4) | K5: article | N5: 7 | O5: https://philarchive.org/archive/NOVAAL | P5: No action - already held
A6: caviola_forth | B6: Yes | C6: Yes | D6: core | E6: core | F6: public_attitudes | G6: Caviola, L. | H6: 2026 | I6: AI consciousness will divide society | J6: in Chace & Lappas (Eds.), Perspectives on Machine Consciousness, CRC Press | K6: chapter | L6: philosophy | M6: public_perception;moral_status | N6: 0 | O6: https://osf.io/preprints/psyarxiv/sntva | P6: No action - already held
A7: birch2025 | B7: Yes | C7: Yes | D7: core | E7: core | F7: consciousness | G7: Birch, J. | H7: 2025 | I7: AI Consciousness: A Centrist Manifesto | J7: PhilPapers | K7: article | L7: philosophy | M7: consciousness_theory;public_perception | N7: 41 | O7: https://philpapers.org/rec/BIRACA-4 | P7: No action - already held
A8: salib2024b | B8: Yes | C8: Verify | E8: core | F8: ai_rights | G8: Salib, P.; Goldstein, S. | H8: 2024 | I8: AI Rights for Economic Flourishing | J8: SSRN 5353214 | K8: preprint | O8: https://papers.ssrn.com/sol3/papers.cfm?abstract_id=5353214 | P8: Verify against corpus record | Q8: Corpus holds 'AI Rights for Human Flourishing' (Salib & Goldstein, 2025) - may be this paper retitled on publication. Confirm against SSRN 5353214 before collecting
A9: salib2024a | B9: Yes | C9: No | E9: core | F9: ai_rights | G9: Salib, P.; Goldstein, S. | H9: 2024 | I9: AI Rights for Human Safety | J9: SSRN 4913167 | K9: preprint | O9: https://papers.ssrn.com/sol3/papers.cfm?abstract_id=4913167 | P9: Collect | Q9: Checked by hand: corpus holds only 'AI Rights for Human Flourishing'; this is a distinct paper
A10: goldstein2026 | B10: Yes | C10: Yes | D10: core | E10: core | F10: ai_rights | G10: Goldstein, S. et al. | H10: 2026 | I10: AI Suffrage for Human Flourishing | J10: Fordham Law Review | K10: article | L10: philosophy | M10: rights_law | N10: 0 | O10: https://papers.ssrn.com/sol3/papers.cfm?abstract_id=6498678 | P10: No action - already held
A11: goldstein2025 | B11: Yes | C11: Yes | D11: core | E11: core | F11: moral_status | G11: Goldstein, S.; Kirk-Giannini, C. D. | H11: 2025 | I11: AI Wellbeing | J11: arXiv 2509.11913 | K11: preprint | L11: philosophy | M11: welfare;moral_status | N11: 23 | O11: https://arxiv.org/abs/2509.11913 | P11: No action - already held
A12: sirbu2026 | B12: Yes | C12: No | E12: core | F12: architectures | G12: Sirbu, R. A.; Floridi, L. | H12: 2026 | I12: An Analysis of the Governance, Ethical, Legal and Social Implications of Biocomputing | J12: Science and Engineering Ethics | K12: article | O12: https://doi.org/10.1007/s11948-025-00572-x | P12: Collect
A13: bruner2022 | B13: Yes | C13: No | E13: core | F13: juridical_personhood | G13: Bruner, C. | H13: 2022 | I13: Artificially Intelligent Boards and the Future of Delaware Corporate Law | J13: Journal of Corporate Law Studies 22(4) | K13: article | O13: https://digitalcommons.law.uga.edu/fac_artchop/1554/ | P13: Collect
A14: weinberg2026 | B14: Yes | C14: No | E14: marginal | F14: exclusion_bills | G14: Weinberg, M. | H14: 2026 | I14: California Sees Ways AI Can Support Policymaking. Here's What It Needs to Succeed | J14: Carnegie Endowment | K14: report | O14: https://carnegieendowment.org/posts/2026/03/california-ai-sb-1159 | P14: Hold (marginal)
A15: block2025 | B15: Yes | C15: Yes | D15: core | E15: core | F15: consciousness | G15: Block, N. | H15: 2025 | I15: Can only meat machines be conscious? | J15: Trends in Cognitive Sciences | K15: article | L15: philosophy | M15: consciousness_theory | O15: https://philarchive.org/rec/BLOCOM-3 | P15: No action - already held
A16: fordham2025 | B16: Yes | C16: No | E16: marginal | F16: juridical_personhood | G16: Fordham, R. F. | H16: 2025 | I16: Citizens United and the Decline of US Democracy: Assessing the Decision's Impact 15 Years Later | J16: Roosevelt Institute | K16: report | O16: https://rooseveltinstitute.org/publications/citizens-united-15-years-later/ | P16: Hold (marginal)
A17: seth2025 | B17: Yes | C17: Yes | D17: core | E17: core | F17: consciousness | G17: Seth, A. K. | H17: 2025 | I17: Conscious artificial intelligence and biological naturalism | J17: Behavioral and Brain Sciences 48, e89 | K17: article | L17: cognitive_science_neuroscience | M17: consciousness_theory;moral_status | N17: 214 | O17: https://doi.org/10.1017/S0140525X25000032 | P17: No action - already held
A18: vangulick2026 | B18: Yes | C18: Yes | D18: canon | E18: core | F18: consciousness | G18: Van Gulick, R. | H18: 2026 | I18: Consciousness | J18: Stanford Encyclopedia of Philosophy | K18: encyclopedia | L18: philosophy | M18: consciousness_theory | N18: 125 | O18: https://plato.stanford.edu/archives/spr2026/entries/consciousness/ | P18: No action - already held
A19: butlin2023 | B19: Yes | C19: No | E19: core | F19: consciousness | G19: Butlin, P. et al. | H19: 2023 | I19: Consciousness in Artificial Intelligence: Insights from the Science of Consciousness | J19: arXiv 2308.08708 | K19: preprint | O19: https://arxiv.org/abs/2308.08708 | P19: Collect | Q19: Checked by hand: corpus holds other Butlin works (Identifying indicators of consciousness, 2025) but NOT the arXiv 2308.08708 report
A20: ryan2021 | B20: Yes | C20: No | E20: core | F20: rights_of_nature | G20: Ryan, E.; Curry, H. P.; Rule, H. | H20: 2021 | I20: Environmental Rights for the 21st Century: A Comprehensive Analysis of the Public Trust Doctrine and Rights of Nature Movement | J20: Cardozo Law Review 42(6) | K20: article | O20: https://larc.cardozo.yu.edu/clr/vol42/iss6/8/ | P20: Collect
A21: alexander2026 | B21: Yes | C21: Yes | D21: core | E21: core | F21: legal_personhood | G21: Alexander et al. | H21: 2026 | I21: How Should the Law Treat Future AI Systems? Fictional Legal Personhood versus Legal Identity | J21: Case Western Journal of Law, Technology & the Internet | K21: article | L21: law | M21: rights_law | O21: https://scholarlycommons.law.case.edu/jolti/vol17/iss1/3/ | P21: No action - already held
A22: arbel2026 | B22: Yes | C22: Yes | D22: core | E22: core | F22: legal_personhood | G22: Arbel, Y.; Salib, P.; Goldstein, S. | H22: 2026 | I22: How to Count AIs: Individuation and Liability for AI Agents | J22: arXiv 2603.10028 | K22: preprint | L22: law | M22: rights_law | O22: https://arxiv.org/abs/2603.10028 | P22: No action - already held
A23: shiller2026 | B23: Yes | C23: Yes | D23: core | E23: core | F23: consciousness | G23: Shiller, D. et al. | H23: 2026 | I23: Initial results of the Digital Consciousness Model | J23: arXiv 2601.17060 | K23: preprint | L23: computer_science_ai | M23: detection_measurement;consciousness_theory | N23: 0 | O23: https://arxiv.org/abs/2601.17060 | P23: No action - already held
A24: bengio2026 | B24: Yes | C24: No | E24: core | F24: ai_safety | G24: Bengio, Y. et al. | H24: 2026 | I24: International AI Safety Report 2026 | J24: arXiv 2602.21012 | K24: report | O24: https://arxiv.org/abs/2602.21012 | P24: Collect
A25: carlsmith2022 | B25: Yes | C25: Yes | D25: adjacent | E25: core | F25: ai_safety | G25: Carlsmith, J. | H25: 2022 | I25: Is Power-Seeking AI an Existential Risk? | J25: arXiv 2206.13353 | K25: preprint | N25: 37 | O25: https://arxiv.org/abs/2206.13353 | P25: No action - already held
A26: wei2023 | B26: Yes | C26: No | E26: core | F26: capabilities | G26: Wei, A. et al. | H26: 2023 | I26: Jailbroken: How Does LLM Safety Training Fail? | J26: arXiv 2307.02483 | K26: preprint | O26: https://arxiv.org/abs/2307.02483 | P26: Collect
A27: jones2025 | B27: Yes | C27: Yes | D27: adjacent | E27: core | F27: capabilities | G27: Jones, C. R.; Bergen, B. K. | H27: 2025 | I27: Large Language Models Pass the Turing Test | J27: arXiv 2503.23674 | K27: preprint | N27: 10 | O27: https://arxiv.org/abs/2503.23674 | P27: No action - already held
A28: okeefe2025 | B28: Yes | C28: No | E28: core | F28: ai_rights | G28: O'Keefe, C. et al. | H28: 2025 | I28: Law-following AI: Designing AI agents to obey human laws | J28: Fordham Law Review 94(1) | K28: article | O28: https://law-ai.org/law-following-ai/ | P28: Collect
A29: solum1992 | B29: Yes | C29: Yes | D29: adjacent | E29: core | F29: legal_personhood | G29: Solum, L. B. | H29: 1992 | I29: Legal Personhood for Artificial Intelligences | J29: North Carolina Law Review 70(4) | K29: article | N29: 88 | O29: https://scholarship.law.unc.edu/nclr/vol70/iss4/4/ | P29: No action - already held
A30: liebman2026 | B30: Yes | C30: Yes | D30: core | E30: core | F30: exclusion_bills | G30: Liebman, M. | H30: 2026 | I30: Legislating Nonpersonhood | J30: Wake Forest Law Review 61:115 | K30: article | L30: law | M30: rights_law | N30: 1 | O30: https://www.wakeforestlawreview.com/2026/04/legislating-nonpersonhood/ | P30: No action - already held
A31: ivanov2022 | B31: Yes | C31: No | E31: core | F31: architectures | G31: Ivanov, D. et al. | H31: 2022 | I31: Neuromorphic artificial intelligence systems | J31: Frontiers in Neuroscience | K31: article | O31: https://www.frontiersin.org/journals/neuroscience/articles/10.3389/fnins.2022.959626/full | P31: Collect | Q31: Checked by hand: corpus neuromorphic entries are different papers (Shiller 2025, Wang 2025)
A32: buck2024 | B32: Yes | C32: No | E32: marginal | F32: definitions | G32: Buck, S. | H32: 2024 | I32: Regulating AI Is Confusing | J32: The Good Science Project | K32: blog | O32: https://goodscience.substack.com/p/regulating-ai-is-confusing | P32: Hold (marginal)
A33: bariach2026 | B33: Yes | C33: Yes | D33: core | E33: core | F33: consciousness_attribution | G33: Bariach, B. et al. | H33: 2026 | I33: Seemingly Conscious AI Risks | J33: SSRN | K33: preprint | L33: computer_science_ai | M33: detection_measurement;public_perception;safety_alignment | O33: https://papers.ssrn.com/sol3/papers.cfm?abstract_id=6588659 | P33: No action - already held
A34: curhan2025 | B34: Yes | C34: No | E34: marginal | F34: fetal_personhood | G34: Curhan, et al. | H34: 2025 | I34: State Policy Trends 2025: Midyear Analysis | J34: Guttmacher Institute | K34: report | O34: https://www.guttmacher.org/2025/06/state-policy-trends-midyear-analysis | P34: Hold (marginal)
A35: long2024 | B35: Yes | C35: Yes | D35: core | E35: core | F35: moral_status | G35: Long, R. et al. | H35: 2024 | I35: Taking AI Welfare Seriously | J35: arXiv 2411.00986 | K35: preprint | L35: philosophy | M35: welfare;moral_status | N35: 152 | O35: https://arxiv.org/abs/2411.00986 | P35: No action - already held
A36: roberts2026 | B36: Yes | C36: No | E36: marginal | F36: exclusion_bills | G36: Roberts, O. | H36: 2026 | I36: Tennessee's AI Bill Would Criminalize the Training of AI Chatbots | J36: National Law Review | K36: commentary | O36: https://natlawreview.com/article/tennessees-ai-bill-would-criminalize-training-ai-cha | P36: Hold (marginal)
A37: lerchner2026 | B37: Yes | C37: Yes | D37: core | E37: core | F37: consciousness | G37: Lerchner, A. | H37: 2026 | I37: The Abstraction Fallacy: Why AI Can Simulate But Not Instantiate Consciousness | J37: PhilArchive / Google DeepMind | K37: preprint | L37: philosophy | M37: consciousness_theory | O37: https://deepmind.google/research/publications/231971/ | P37: No action - already held
A38: hanson2016 | B38: Yes | C38: Yes | D38: core | E38: core | F38: digital_minds_futures | G38: Hanson, R. | H38: 2016 | I38: The Age of Em: Work, Love, and Life when Robots Are Smart | J38: Oxford University Press | K38: book | L38: social_sciences | M38: identity_individuation;culture_media | N38: 4 | P38: No action - already held
A39: blair2015 | B39: Yes | C39: No | E39: core | F39: juridical_personhood | G39: Blair, M. M.; Pollman, E. | H39: 2015 | I39: The Derivative Nature of Corporate Constitutional Rights | J39: William & Mary Law Review 56(5) | K39: article | O39: https://papers.ssrn.com/sol3/papers.cfm?abstract_id=2611299 | P39: Collect
A40: birch2024 | B40: Yes | C40: Yes | D40: core | E40: core | F40: moral_status | G40: Birch, J. | H40: 2024 | I40: The Edge of Sentience: Risk and Precaution in Humans, Other Animals, and AI | J40: Oxford University Press | K40: book | L40: philosophy | M40: detection_measurement;welfare | N40: 0 | P40: No action - already held
...

Sheet Evidence
A1: ref_key | B1: authors_or_source | C1: year | D1: title | E1: outlet | F1: evidence_type | G1: jurisdiction | H1: related_bill | I1: url
A2: abdurasulov2025 | B2: Abdurasulov, A. | C2: 2025 | D2: The new AI arms race changing the war in Ukraine | E2: BBC News | F2: news | I2: https://www.bbc.co.uk/news/articles/cly7jrez2jno
A3: alexander_simon2025 | B3: Alexander, H.; Simon, J. | C3: 2025 | D3: Ohio's AI Personhood Ban Risks Outlawing the Future | E3: Ohio Capital Journal | F3: op_ed | G3: OH | H3: HB 469 | I3: https://ohiocapitaljournal.com/2025/11/25/ohios-ai-personhood-ban-risks-outlawing-the-future/
A4: allianceai_a | B4: Alliance for Secure AI Action | C4: n.d. | D4: The Alliance for Secure AI Action | E4: Organisation site | F4: advocacy | I4: https://secureainow.org/
A5: allianceai_b | B5: Alliance for Secure AI Action | C5: n.d. | D5: The Alliance for Secure AI Staff | E5: Organisation site | F5: advocacy | I5: https://secureainow.org/staff/
A6: amipodcast2025 | B6: Am I? Podcast | C6: 2025 | D6: Lawmaker Explains Why He Wants to Outlaw AI Consciousness | E6: Podcast | F6: media | G6: OH | H6: HB 469 | I6: https://podcasts.apple.com/us/podcast/am-i-id1834212843?i=1000740865127
A7: aquinas | B7: Aquinas, T. | C7: ca. 1270 | D7: Summa Theologiae, Prima Pars, Question 93 | E7: - | F7: primary_religious
A8: ball2025a | B8: Ball, D. | C8: 2025 | D8: Tweet reply on TN SB 1493 and the First Amendment | E8: X (Twitter) | F8: social | G8: TN | H8: HB 1455 / SB 1493 | I8: https://x.com/deanwball/status/2004678006561013931
A9: ball2025b | B9: Ball, D. | C9: 2025 | D9: Tweet commenting on TN SB 1493 | E9: X (Twitter) | F9: social | G9: TN | H9: HB 1455 / SB 1493 | I9: https://x.com/deanwball/status/2004637387402416246
A10: ball_bio | B10: Ball, D. | C10: n.d. | D10: Dean W. Ball - Biography | E10: Personal site | F10: bio | I10: https://www.deanball.com/
A11: banutah_complaint | B11: Ban v. Utah complaint | C11: 2025 | D11: No. 250900869 (Utah Dist. Ct.) | E11: Court filing | F11: legal_doc | G11: UT | H11: HB 249 | I11: https://www.nonhumanrights.org/wp-content/uploads/2025/01/UT-Complaint.pdf
A12: banutah_dismissal | B12: Ban v. Utah dismissal order | C12: 2025 | D12: Memorandum decision and order granting motion to dismiss | E12: Court order | F12: legal_doc | G12: UT | H12: HB 249
A13: barker2026 | B13: Barker, D. | C13: 2026 | D13: Testimony on AB 959 before the Wisconsin Assembly Cttee on Science, Technology and AI | E13: Wisconsin Legislature | F13: testimony | G13: WI | H13: AB 959 / SB 932 | I13: https://docs.legis.wisconsin.gov/misc/lc/hearing_testimony_and_materials/2025/ab959/ab0959_2026_02_04.pdf
A14: berg2025 | B14: Berg, C.; Rosenblatt, J. | C14: 2025 | D14: If AI Becomes Conscious, We Need to Know | E14: Wall Street Journal | F14: op_ed | I14: https://www.wsj.com/opinion/if-ai-becomes-conscious-we-need-to-know-83aa61d8
A15: berry2026 | B15: Berry, S. | C15: 2026 | D15: Testimony on Missouri HB 1746 | E15: Missouri House of Representatives | F15: testimony | G15: MO | H15: HB 1746 | I15: https://documents.house.mo.gov/billtracking/bills261/witnesses/HB1746Testimony2-2.pdf
A16: bible | B16: Bible | C16: - | D16: Genesis 1:26-27 | E16: - | F16: primary_religious
A17: blacks2001 | B17: Black's Law Dictionary | C17: 2001 | D17: 2nd pocket edn (Bryan A. Garner, ed.) | E17: West Group | F17: reference_work
A18: boone2022 | B18: Boone, R. | C18: 2022 | D18: Bill Would Bar Idaho's Lands and Animals From 'Personhood' | E18: Associated Press | F18: news | G18: ID | H18: HB 720 | I18: https://apnews.com/article/united-states-environment-animals-idaho-402c779428a74a6ec9e7994ee977005c
A19: brill2026 | B19: Brill, L. | C19: 2026 | D19: Testimony on AB 959 before the Wisconsin Assembly Committee | E19: Wisconsin Legislature | F19: testimony | G19: WI | H19: AB 959 / SB 932 | I19: https://docs.legis.wisconsin.gov/misc/lc/hearing_testimony_and_materials/2025/ab959/ab0959_2026_02_04.pdf
A20: claggett2025 | B20: Claggett, T. | C20: 2025 | D20: Sponsor testimony on HB 469, Ohio House Technology and Innovation Cttee | E20: Ohio House of Representatives | F20: testimony | G20: OH | H20: HB 469 | I20: https://ohiohouse.gov/committees/technology-and-innovation/bills/hb469
A21: maynard_nd | B21: Cody Maynard for Oklahoma | C21: n.d. | D21: Endorsements | E21: Campaign site | F21: advocacy | G21: OK | H21: HB 3546 | I21: https://codymaynard.com/home/endorsements/
A22: colbert2025 | B22: Colbert, S. | C22: 2025 | D22: The A.I. Stock Bubble | ChatGPT, Grok, Go Erotic | Banning Human-Chatbot Marriage | E22: YouTube | F22: media | I22: https://www.youtube.com/watch?v=o-u_ZkGBcNc
A23: copp2026 | B23: Copp, T. et al. | C23: 2026 | D23: Anthropic's AI tool Claude central to U.S. campaign in Iran, amid a bitter feud | E23: Washington Post | F23: news | I23: https://www.washingtonpost.com/technology/2026/03/04/anthropic-ai-iran-campaign/
A24: cornell_lii | B24: Cornell Legal Information Institute | C24: n.d. | D24: Wex Legal Definitions (Natural Person; Artificial Person) | E24: Legal Information Institute | F24: reference_work | I24: https://www.law.cornell.edu/wex/natural_person
A25: dodson2023 | B25: Dodson, C. | C25: 2023 | D25: Oral testimony on HB 1361 before the North Dakota Legislative Assembly | E25: North Dakota Legislative Assembly | F25: testimony | G25: ND | H25: HB 1361 | I25: https://video.ndlegis.gov/en/PowerBrowser/PowerBrowserV2/20230306/-1/29325
A26: douthat2026 | B26: Douthat, R.; Alvarez Boyd, S. | C26: 2026 | D26: Anthropic's Chief on A.I.: We Don't Know if the Models Are Conscious | E26: New York Times | F26: news | I26: https://www.nytimes.com/2026/02/12/opinion/artificial-intelligence-anthropic-amodei.html
A27: earthlaw2024 | B27: Earth Law Center | C27: 2024 | D27: Utah Advances Anti-Rights of Nature Bill with Implications for AI | E27: Earth Law Center | F27: advocacy | G27: UT | H27: HB 249 | I27: https://www.earthlawcenter.org/blog-entries/2024/2/utah-advances-anti-rights-of-nature-bill-with-implications-for-ai
A28: edmonson2025 | B28: Edmonson, D. | C28: 2025 | D28: RE: HB 469, concerns (testimony to Ohio House Cttee on Technology and Innovation) | E28: Ohio House of Representatives | F28: testimony | G28: OH | H28: HB 469 | I28: https://ohiohouse.gov/committees/technology-and-innovation/bills/hb469
A29: evans2025 | B29: Evans, N. | C29: 2025 | D29: What's in Ohio's Proposal Banning AI Personhood | E29: Ohio Capital Journal | F29: news | G29: OH | H29: HB 469 | I29: https://ohiocapitaljournal.com/2025/11/17/whats-in-ohios-proposal-banning-ai-personhood/
A30: fli_a | B30: Future of Life Institute | C30: n.d. | D30: About us | E30: FLI | F30: advocacy | I30: https://futureoflife.org/about-us/
A31: fli_b | B31: Future of Life Institute | C31: n.d. | D31: Home | E31: FLI | F31: advocacy | I31: https://futureoflife.org/
A32: hochul2025 | B32: Governor Kathy Hochul | C32: 2025 | D32: Governor Hochul Signs Legislation to Require AI Frameworks for AI Frontier Models | E32: NY Governor's Office | F32: press_release | G32: NY | I32: https://www.governor.ny.gov/news/governor-hochul-signs-nation-leading-legislation-require-ai-frameworks-ai-frontier-models
A33: guardian2022 | B33: Guardian | C33: 2022 | D33: Happy the elephant is not a person, says court in key US animal rights case | E33: The Guardian | F33: news | I33: https://www.theguardian.com/us-news/2022/jun/14/elephant-person-animal-rights-happy
A34: hardin2026 | B34: Hardin, C. | C34: 2026 | D34: Governor DeSantis Directs Florida State Agencies to Partner with FLI to Shield Families from AI Harm | E34: Future of Life Institute | F34: press_release | G34: FL | I34: https://futureoflife.org/press-release/desantis-directs-florida-agencies-to-partner-with-fli/
A35: mo_hb1746_test | B35: HB 1746 testimony before the Missouri House Emerging Issues Committee | C35: 2026 | D35: Committee testimony record | E35: Missouri House of Representatives | F35: testimony | G35: MO | H35: HB 1746 | I35: https://documents.house.mo.gov/billtracking/bills261/witnesses/HB1746Testimony2-2.pdf
A36: mo_hb1769_test | B36: HB 1769 testimony before the Missouri House Emerging Issues Committee | C36: 2026 | D36: Committee testimony record | E36: Missouri House of Representatives | F36: testimony | G36: MO | H36: HB 1769 | I36: https://documents.house.mo.gov/billtracking/bills261/witnesses/HB1769Testimony2-2.pdf
A37: hill2022 | B37: Hill, M. | C37: 2022 | D37: Court must decide if an elephant is a person | E37: Associated Press via KSL | F37: news | I37: https://www.ksl.com/article/50407168/court-must-decide-if-an-elephant-is-a-person
A38: iff2022 | B38: Idaho Freedom Foundation | C38: 2022 | D38: House Bill 720 - Personhood, animals, objects | E38: Idaho Freedom Foundation | F38: advocacy | G38: ID | H38: HB 720 | I38: https://idahofreedom.org/house-bill-720-personhood-animals-objects/
A39: littleton_nd | B39: Littleton, M. | C39: n.d. | D39: Tennessee House of Representatives member page | E39: Tennessee General Assembly | F39: member_page | G39: TN | H39: HB 1455 | I39: https://wapp.capitol.tn.gov/apps/LegislatorInfo/member?district=h78
A40: maisonnave2023 | B40: Maisonnave et al. | C40: 2023 | D40: Indigenous leader inspires an Amazon city to grant personhood to an endangered river | E40: AP News | F40: news | I40: https://apnews.com/article/brazil-amazon-wari-indigenous-nature-rights-deforestation-68af65663fb7bd1b9d2051ce10c17a46
...

Sheet Cases
A1: case | B1: citation | C1: court | D1: year | E1: relevance_in_paper
A2: Ban v. Utah | B2: No. 250900869 | C2: Utah Dist. Ct. | D2: 2025 | E2: NhRP challenge to HB 249; dismissed 8 May 2025
A3: Bank Markazi v. Peterson | B3: 578 U.S. 212 | C3: U.S. Supreme Court | D3: 2016 | E3: Congress may amend law affecting pending litigation
A4: Citizens United v. FEC | B4: 558 U.S. 310 | C4: U.S. Supreme Court | D4: 2010 | E4: First Amendment protection for corporate political spending
A5: Cleveland Board of Education v. LaFleur | B5: 414 U.S. 632 | C5: U.S. Supreme Court | D5: 1974 | E5: Irrebuttable presumptions and due process
A6: Coates v. Cincinnati | B6: 402 U.S. 611 | C6: U.S. Supreme Court | D6: 1971 | E6: Vagueness: criminalising 'annoying' behaviour
A7: Connally v. General Construction Co. | B7: 269 U.S. 385 | C7: U.S. Supreme Court | D7: 1926 | E7: Vagueness: 'current rate of per diem wages'
A8: Daubert v. Merrell Dow Pharmaceuticals | B8: 509 U.S. 579 | C8: U.S. Supreme Court | D8: 1993 | E8: Admissibility standard for scientific evidence
A9: Epperson v. Arkansas | B9: 393 U.S. 97 | C9: U.S. Supreme Court | D9: 1968 | E9: Establishment Clause; teaching of evolution
A10: FCC v. Beach Communications | B10: 508 U.S. 307 | C10: U.S. Supreme Court | D10: 1993 | E10: Rational basis test
A11: Kennedy v. Bremerton School District | B11: 597 U.S. 507 | C11: U.S. Supreme Court | D11: 2022 | E11: Free Exercise; personal religious observance
A12: Kitzmiller v. Dover Area School District | B12: 400 F. Supp. 2d 707 | C12: M.D. Pa. | D12: 2005 | E12: Establishment Clause; intelligent design
... A16: United States v. Klein | B16: 80 U.S. (13 Wall.) 128 | C16: U.S. Supreme Court | D16: 1871 | E16: Congress may not prescribe a rule of decision

Sheet Summary
A1: Summary
A3: Literature working set (total rows) | B3: =COUNTA(Literature!A2:A111) | C3: Union of paper scholarly refs and corpus personhood cluster
A4: Cited by the paper | B4: =COUNTIF(Literature!B2:B111,"Yes") | C4: in_paper = Yes
A5: Already held in DM corpus | B5: =COUNTIF(Literature!C2:C111,"Yes") | C5: in_corpus = Yes
A6: Needs verification | B6: =COUNTIF(Literature!C2:C111,"Verify") | C6: Possible retitled duplicate
A7: Paper refs already in corpus | B7: =COUNTIFS(Literature!B2:B111,"Yes",Literature!C2:C111,"Yes") | C7: The dedupe saving
A8: Paper refs NOT in corpus (to collect) | B8: =COUNTIFS(Literature!B2:B111,"Yes",Literature!C2:C111,"No") | C8: New acquisitions
A9: Corpus works the paper missed | B9: =COUNTIFS(Literature!B2:B111,"No",Literature!C2:C111,"Yes") | C9: Finding A: corpus as a source
A11: Tier: core | B11: =COUNTIF(Literature!E2:E111,"core")
A12: Tier: marginal | B12: =COUNTIF(Literature!E2:E111,"marginal")
A14: Action: no action - already held | B14: =COUNTIF(Literature!P2:P111,"No action - already held")
A15: Action: verify against corpus record | B15: =COUNTIF(Literature!P2:P111,"Verify against corpus record")
A16: Action: collect | B16: =COUNTIF(Literature!P2:P111,"Collect")
A17: Action: hold (marginal) | B17: =COUNTIF(Literature!P2:P111,"Hold (marginal)")
A18: Action: classify for tracker | B18: =COUNTIF(Literature!P2:P111,"Classify for tracker")
A20: Evidence records (total) | B20: =COUNTA(Evidence!A2:A81) | C20: Source records for the Phase 2 bill registry
A21: Testimony | B21: =COUNTIF(Evidence!F2:F81,"testimony")
A22: News | B22: =COUNTIF(Evidence!F2:F81,"news")
A23: Advocacy | B23: =COUNTIF(Evidence!F2:F81,"advocacy")
A24: Legal documents | B24: =COUNTIF(Evidence!F2:F81,"legal_doc")
A25: Op-eds | B25: =COUNTIF(Evidence!F2:F81,"op_ed")
A26: Social posts | B26: =COUNTIF(Evidence!F2:F81,"social")
A27: Press releases | B27: =COUNTIF(Evidence!F2:F81,"press_release")
A28: Other (media, bio, reference, religious, gov) | B28: =COUNTA(Evidence!A2:A81)-SUM(B19:B25)
A30: Cases in Table of Cases | B30: =COUNTA(Cases!A2:A16)
A32: Total reference-list entries accounted for | B32: =COUNTIFS(Literature!B2:B111,"Yes")+COUNTA(Evidence!A2:A81) | C32: Scholarly + evidence = the paper's reference list
A33: Scholarly share of reference list | B33: =COUNTIFS(Literature!B2:B111,"Yes")/(COUNTIFS(Literature!B2:B111,"Yes")+COUNTA(Evidence!A2:A81)) | C33: Scholarly / (scholarly + evidence)
